<?xml version="1.0"?>

<robot xmlns:xacro="http://ros.org/wiki/xacro" name="p3at">

<!-- Macros -->
	<xacro:macro name="p3at_wheel" params="fb lr xyz reflect">

		<!-- Axle -->
		<link name="p3at_${fb}_${lr}_axle">
			<inertial>
				<mass value="0.1"/>	
				<origin xyz="0 0 0"/>
				<inertia ixx="1.0" ixy="0.0" ixz="0.0"
					 iyy="1.0" iyz="0.0" izz="1.0"/>
	  	 	</inertial>
			<visual name="base_visual">
				<origin xyz="0 0 0" rpy="0 0 0"/>
				<geometry name="pioneer_geom">
					<mesh filename="package://p2os_urdf/meshes/p3at_meshes/axle.stl"/>
				</geometry>
				<material name="AxleGrey">
					<color rgba="0.5 0.5 0.5 1"/>
				</material>
			</visual>
			<collision>
				<origin xyz="0 0 0" rpy="0 0 0"/>
				<geometry>
					<box size="0 0 0"/>
				</geometry>
			</collision>
		</link>

		<gazebo reference="p3at_${fb}_${lr}_axle">
			<material value="Gazebo/Grey"/>
		</gazebo>

		<!-- Wheel-Hub -->
		<link name="p3at_${fb}_${lr}_hub">
			<inertial>
				<mass value="0.1"/>	
				<origin xyz="0 0 0"/>
				<inertia ixx="1.0" ixy="0.0" ixz="0.0"
					 iyy="1.0" iyz="0.0" izz="1.0"/>
	  	 	</inertial>
			<visual name="base_visual">
				<origin xyz="0 0 0" rpy="0 0 0"/>
				<geometry name="pioneer_geom">
					<mesh filename="package://p2os_urdf/meshes/p3at_meshes/${lr}_hubcap.stl"/>
				</geometry>
				<material name="HubcapYellow">
					<color rgba="1.0 0.811 0.151 1.0"/>
				</material>
			</visual>
			<collision>
				<origin xyz="0 0 0" rpy="0 0 0"/>
				<geometry>
					<box size="0 0 0"/>
				</geometry>
			</collision>
		</link>

		<gazebo reference="p3at_${fb}_${lr}_hub">
			<material value="Gazebo/Yellow"/>
		</gazebo>	

		<!-- Wheel -->
		<link name="p3at_${fb}_${lr}_wheel">
			<inertial>
				<mass value="0.5"/>	
				<origin xyz="0 0 0"/>
				<inertia ixx="0.012411765597" ixy="0" ixz="0" iyy="0.015218160428" iyz="0" izz="0.011763977943"/>
			</inertial>
			<visual name="base_visual">
				<origin xyz="0 0 0" rpy="0 0 0"/>
				<geometry name="pioneer_geom">
					<mesh filename="package://p3at/meshes/wheel.stl"/>
				</geometry>
				<material name="WheelBlack">
					<color rgba="0.117 0.117 0.117 1"/>
				</material>
			</visual>
			<collision>
				<origin xyz="0 0 0" rpy="${-3.1415927/2} 0 0"/>
				<geometry>
					<cylinder radius="0.111" length="0.075"/>
				</geometry>
			</collision>
		</link>

		<!-- Wheel joints -->
		<joint name="p3at_${fb}_${lr}_base_axle_joint" type="fixed">
			<origin xyz="${xyz}" rpy="0 0 0"/>
			<parent link="base_link"/>
			<child link="p3at_${fb}_${lr}_axle"/>
		</joint>

		<joint name="p3at_${fb}_${lr}_axle_hub_joint" type="fixed">
			<origin xyz="0 ${reflect*0.041} 0" rpy="0 0 0"/>
			<parent link="p3at_${fb}_${lr}_axle"/>
			<child link="p3at_${fb}_${lr}_hub"/>
		</joint>

		<joint name="p3at_${fb}_${lr}_hub_wheel_joint" type="continuous">
			<axis xyz="0 1 0"/>
			<anchor xyz="0 0 0"/>
			<limit effort="100" velocity="100" />
			<joint_properties damping="0.7"/>
			<origin xyz="0 0 0" rpy="0 0 0"/>
			<parent link="p3at_${fb}_${lr}_hub"/>
			<child link="p3at_${fb}_${lr}_wheel"/>
		</joint>

		<gazebo reference="p3at_${fb}_${lr}_wheel">
			<material value="Gazebo/Black"/>
			<minDepth>0.001</minDepth>
			<kp>10000000.0</kp>
			<kd>1.0</kd>
			<fdir1 value="1 0 0"/>
			<mu1>0.6</mu1>
			<mu2>0.2</mu2>
		</gazebo>
	</xacro:macro>

	<xacro:macro name="p3at_controller" params="ns">
		<gazebo>
			<plugin name="skid_steer_drive_controller" filename="libgazebo_ros_skid_steer_drive.so">
				<updateRate>100.0</updateRate>
				<robotNamespace>${ns}</robotNamespace>

				<leftFrontJoint>p3at_front_left_hub_wheel_joint</leftFrontJoint>
				<rightFrontJoint>p3at_front_right_hub_wheel_joint</rightFrontJoint>
				<leftRearJoint>p3at_back_left_hub_wheel_joint</leftRearJoint>
				<rightRearJoint>p3at_back_right_hub_wheel_joint</rightRearJoint>

				<wheelSeparation>0.4</wheelSeparation>
				<wheelDiameter>0.215</wheelDiameter>
				<robotBaseFrame>base_link</robotBaseFrame>
				<odometryFrame>odom</odometryFrame>
				<torque>200</torque>
				<commandTopic>cmd_vel</commandTopic>
				<odometryTopic>odom</odometryTopic>
				<broadcastTF>1</broadcastTF>
			</plugin>
		</gazebo>
	</xacro:macro>

<!-- Robot definition -->

	<!-- Chassis -->
	<link name="base_link">
		<inertial>
			<mass value="30.0"/>
			<origin xyz="0 0 0.177"/>
			<inertia ixx="0.3338" ixy="0.0" ixz="0.0"
				iyy="0.4783" iyz="0.0"
				izz="0.3338"/>
		</inertial>
		<visual name="base_visual">
			<origin xyz="0 0 0.177" rpy="0 0 0"/>
			<geometry name="pioneer_geom">
				<mesh filename="package://p2os_urdf/meshes/p3at_meshes/chassis.stl"/>
			</geometry>
			<material name="ChassisRed">
				<color rgba="0.851 0.0 0.0 1.0"/>
			</material>
		</visual>
		<collision>
			<origin xyz="0 0 0.177" rpy="0 0 0"/>
				<geometry>
					<mesh filename="package://p2os_urdf/meshes/p3at_meshes/chassis.stl"/>
				</geometry>
		</collision>
	</link>

	<gazebo reference="base_link">
		<material value="Gazebo/Red"/>
	</gazebo>

	<!-- Top plate -->
	<link name="top_plate">
		<inertial>
			<mass value="0.1"/>	
			<origin xyz="-0.025 0 -0.223"/>
			<inertia ixx="1.0" ixy="0.0" ixz="0.0"
				 iyy="1.0" iyz="0.0"
 				izz="1.0"/>
		</inertial>
		<visual name="base_visual">
			<origin xyz="0 0 0" rpy="0 0 0"/>
			<geometry name="pioneer_geom">
				<mesh filename="package://p2os_urdf/meshes/p3at_meshes/top.stl"/>
			</geometry>
			<material name="TopBlack">
					<color rgba="0.038 0.038 0.038 1.0"/>
			</material>
		</visual>
		<collision>
			<origin xyz="0 0 0" rpy="0 0 0"/>
			<geometry>
				<box size="0 0 0"/>
			</geometry>
		</collision>
	</link>

	<joint name="base_top_joint" type="fixed">
		<origin xyz="0.003 0 0.274" rpy="0 0 0"/>
		<parent link="base_link"/>
		<child link="top_plate"/>
	</joint>

	<gazebo reference="top_plate">
		<material value="Gazebo/Black"/>
	</gazebo>

	<xacro:p3at_wheel lr="left" fb="front"  xyz=" 0.135 0.156 0.111" reflect="1" />
	<xacro:p3at_wheel lr="left" fb="back"   xyz="-0.135 0.156 0.111" reflect="1" />
	<xacro:p3at_wheel lr="right" fb="front" xyz=" 0.135 -0.156 0.111" reflect="-1" />
	<xacro:p3at_wheel lr="right" fb="back"  xyz="-0.135 -0.156 0.111" reflect="-1" />

</robot>
